Workbook

Sheet MATLAB Input
A1: AtomicNumber | B1: Symbol | C1: Element | D1: AtomicMass | E1: AtomicRadius | F1: ChargeNumber | G1: Charge | H1: IonicMass | I1: IonicRadius | J1: Zeta
A2: =Values!A2 -> 1 | B2: =Values!B2 -> H | C2: =Values!C2 -> Hydrogen | D2: =Values!D2 -> 1.6738234e-27 | E2: =Values!E2 -> 1.2e-10 | F2: =ABS(Values!F2) -> 1 | G2: =ABS(Values!G2) -> 1.6e-19 | H2: =Values!H2 -> 1.6729124e-27 | I2: =Values!I2 -> 0 | J2: =Values!J2 -> 0
A3: =Values!A3 -> 2 | B3: =Values!B3 -> He | C3: =Values!C3 -> Helium | D3: =Values!D3 -> 6.6464737e-27 | E3: =Values!E3 -> 1.4e-10 | F3: =ABS(Values!F3) -> 0 | G3: =ABS(Values!G3) -> 0 | H3: =Values!H3 -> 0 | I3: =Values!I3 -> 0 | J3: =Values!J3 -> 0
A4: =Values!A4 -> 3 | B4: =Values!B4 -> Li | C4: =Values!C4 -> Lithium | D4: =Values!D4 -> 1.1623773e-26 | E4: =Values!E4 -> 1.82e-10 | F4: =ABS(Values!F4) -> 1 | G4: =ABS(Values!G4) -> 1.6e-19 | H4: =Values!H4 -> 1.1622863e-26 | I4: =Values!I4 -> 7.6e-11 | J4: =Values!J4 -> 3.4e-12
A5: =Values!A5 -> 4 | B5: =Values!B5 -> Be | C5: =Values!C5 -> Beryllium | D5: =Values!D5 -> 1.4965082e-26 | E5: =Values!E5 -> 1.53e-10 | F5: =ABS(Values!F5) -> 2 | G5: =ABS(Values!G5) -> 3.2e-19 | H5: =Values!H5 -> 1.496326e-26 | I5: =Values!I5 -> 4.5e-11 | J5: =Values!J5 -> 8.4823002e-13
A6: =Values!A6 -> 5 | B6: =Values!B6 -> B | C6: =Values!C6 -> Boron | D6: =Values!D6 -> 1.7950427e-26 | E6: =Values!E6 -> 1.92e-10 | F6: =ABS(Values!F6) -> 0 | G6: =ABS(Values!G6) -> 0 | H6: =Values!H6 -> 0 | I6: =Values!I6 -> 0 | J6: =Values!J6 -> 0
A7: =Values!A7 -> 6 | B7: =Values!B7 -> C | C7: =Values!C7 -> Carbon | D7: =Values!D7 -> 1.9944735e-26 | E7: =Values!E7 -> 1.7e-10 | F7: =ABS(Values!F7) -> 0 | G7: =ABS(Values!G7) -> 0 | H7: =Values!H7 -> 0 | I7: =Values!I7 -> 0 | J7: =Values!J7 -> 0
A8: =Values!A8 -> 7 | B8: =Values!B8 -> N | C8: =Values!C8 -> Nitrogen | D8: =Values!D8 -> 2.3259171e-26 | E8: =Values!E8 -> 1.55e-10 | F8: =ABS(Values!F8) -> 0 | G8: =ABS(Values!G8) -> 0 | H8: =Values!H8 -> 0 | I8: =Values!I8 -> 0 | J8: =Values!J8 -> 0
A9: =Values!A9 -> 8 | B9: =Values!B9 -> O | C9: =Values!C9 -> Oxygen | D9: =Values!D9 -> 2.6566965e-26 | E9: =Values!E9 -> 1.52e-10 | F9: =ABS(Values!F9) -> 2 | G9: =ABS(Values!G9) -> 3.2e-19 | H9: =Values!H9 -> 2.6568786e-26 | I9: =Values!I9 -> 1.4e-10 | J9: =Values!J9 -> 2.6389378e-12
A10: =Values!A10 -> 9 | B10: =Values!B10 -> F | C10: =Values!C10 -> Fluorine | D10: =Values!D10 -> 3.1547591e-26 | E10: =Values!E10 -> 1.35e-10 | F10: =ABS(Values!F10) -> 1 | G10: =ABS(Values!G10) -> 1.6e-19 | H10: =Values!H10 -> 3.1548502e-26 | I10: =Values!I10 -> 1.33e-10 | J10: =Values!J10 -> 2.5069909e-12
A11: =Values!A11 -> 10 | B11: =Values!B11 -> Ne | C11: =Values!C11 -> Neon | D11: =Values!D11 -> 3.3509678e-26 | E11: =Values!E11 -> 1.54e-10 | F11: =ABS(Values!F11) -> 0 | G11: =ABS(Values!G11) -> 0 | H11: =Values!H11 -> 0 | I11: =Values!I11 -> 0 | J11: =Values!J11 -> 0
A12: =Values!A12 -> 11 | B12: =Values!B12 -> Na | C12: =Values!C12 -> Sodium | D12: =Values!D12 -> 3.817541e-26 | E12: =Values!E12 -> 2.27e-10 | F12: =ABS(Values!F12) -> 1 | G12: =ABS(Values!G12) -> 1.6e-19 | H12: =Values!H12 -> 3.8174499e-26 | I12: =Values!I12 -> 1.02e-10 | J12: =Values!J12 -> 3.2e-12
A13: =Values!A13 -> 12 | B13: =Values!B13 -> Mg | C13: =Values!C13 -> Magnesium | D13: =Values!D13 -> 4.0359402e-26 | E13: =Values!E13 -> 1.73e-10 | F13: =ABS(Values!F13) -> 2 | G13: =ABS(Values!G13) -> 3.2e-19 | H13: =Values!H13 -> 4.035758e-26 | I13: =Values!I13 -> 7.2e-11 | J13: =Values!J13 -> 1.357168e-12
... A119: =Values!A119 -> 118 | B119: =Values!B119 -> Og | C119: =Values!C119 -> Oganesson | D119: =Values!D119 -> 4.902177e-25 | E119: =Values!E119 -> 0 | F119: =ABS(Values!F119) -> 0 | G119: =ABS(Values!G119) -> 0 | H119: =Values!H119 -> 0 | I119: =Values!I119 -> 0 | J119: =Values!J119 -> 0
A120: ='10um Microsphere'!A2 -> N/A | B120: ='10um Microsphere'!B2 -> N/A | C120: ='10um Microsphere'!C2 -> Minimum Size, Minimum Charge: 10um Carboxylate-Modified Polystyrene Microsphere | D120: ='10um Microsphere'!D2 -> N/A | E120: ='10um Microsphere'!E2 -> N/A | F120: ='10um Microsphere'!F2 -> N/A | G120: ='10um Microsphere'!G2 -> 4.5338721e-11 | H120: ='10um Microsphere'!H2 -> 4.2455846e-13 | ... J120: ='10um Microsphere'!J2 -> 8.6330966e-08
A121: ='10um Microsphere'!A3 -> N/A | B121: ='10um Microsphere'!B3 -> N/A | C121: ='10um Microsphere'!C3 -> Maximum Size, Minimum Charge: 10um Carboxylate-Modified Polystyrene Microsphere | D121: ='10um Microsphere'!D3 -> N/A | E121: ='10um Microsphere'!E3 -> N/A | F121: ='10um Microsphere'!F3 -> N/A | G121: ='10um Microsphere'!G3 -> 6.1865122e-11 | H121: ='10um Microsphere'!H3 -> 6.7670972e-13 | ... J121: ='10um Microsphere'!J3 -> 1.0084512e-07
A122: ='10um Microsphere'!A4 -> N/A | B122: ='10um Microsphere'!B4 -> N/A | C122: ='10um Microsphere'!C4 -> Average: 10um Carboxylate-Modified Polystyrene Microsphere | D122: ='10um Microsphere'!D4 -> N/A | E122: ='10um Microsphere'!E4 -> N/A | F122: ='10um Microsphere'!F4 -> N/A | G122: ='10um Microsphere'!G4 -> 7.0118167e-11 | H122: ='10um Microsphere'!H4 -> 5.4087739e-13 | ... J122: ='10um Microsphere'!J4 -> 9.3588045e-08
A123: ='10um Microsphere'!A5 -> N/A | B123: ='10um Microsphere'!B5 -> N/A | C123: ='10um Microsphere'!C5 -> Minimum Size, Maximum Charge: 10um Carboxylate-Modified Polystyrene Microsphere | D123: ='10um Microsphere'!D5 -> N/A | E123: ='10um Microsphere'!E5 -> N/A | F123: ='10um Microsphere'!F5 -> N/A | G123: ='10um Microsphere'!G5 -> 7.3992201e-11 | H123: ='10um Microsphere'!H5 -> 4.2455846e-13 | ... J123: ='10um Microsphere'!J5 -> 8.6330966e-08
A124: ='10um Microsphere'!A6 -> N/A | B124: ='10um Microsphere'!B6 -> N/A | C124: ='10um Microsphere'!C6 -> Maximum Size, Maximum Charge: 10um Carboxylate-Modified Polystyrene Microsphere | D124: ='10um Microsphere'!D6 -> N/A | E124: ='10um Microsphere'!E6 -> N/A | F124: ='10um Microsphere'!F6 -> N/A | G124: ='10um Microsphere'!G6 -> 1.0096307e-10 | H124: ='10um Microsphere'!H6 -> 6.7670972e-13 | ... J124: ='10um Microsphere'!J6 -> 1.0084512e-07
A125: ='2um Microsphere'!A2 -> N/A | B125: ='2um Microsphere'!B2 -> N/A | C125: ='2um Microsphere'!C2 -> Minimum Size, Minimum Charge: 2um Carboxylate-Modified Polystyrene Microsphere | D125: ='2um Microsphere'!D2 -> N/A | E125: ='2um Microsphere'!E2 -> N/A | F125: ='2um Microsphere'!F2 -> N/A | G125: =ABS('2um Microsphere'!G2) -> 1.525095e-12 | H125: ='2um Microsphere'!H2 -> 2.6192619e-15 | I125: ='2um Microsphere'!I2 -> 8.4e-07 | J125: ='2um Microsphere'!J2 -> 1.5833627e-08
A126: ='2um Microsphere'!A3 -> N/A | B126: ='2um Microsphere'!B3 -> N/A | C126: ='2um Microsphere'!C3 -> Minimum Size, Maximum Charge: 2um Carboxylate-Modified Polystyrene Microsphere | D126: ='2um Microsphere'!D3 -> N/A | E126: ='2um Microsphere'!E3 -> N/A | F126: ='2um Microsphere'!F3 -> N/A | G126: =ABS('2um Microsphere'!G3) -> 1.7645435e-12 | H126: ='2um Microsphere'!H3 -> 2.6192619e-15 | I126: ='2um Microsphere'!I3 -> 8.4e-07 | J126: ='2um Microsphere'!J3 -> 1.5833627e-08
A127: ='2um Microsphere'!A4 -> N/A | B127: ='2um Microsphere'!B4 -> N/A | C127: ='2um Microsphere'!C4 -> Average: 2um Carboxylate-Modified Polystyrene Microsphere | D127: ='2um Microsphere'!D4 -> N/A | E127: ='2um Microsphere'!E4 -> N/A | F127: ='2um Microsphere'!F4 -> N/A | G127: =ABS('2um Microsphere'!G4) -> 2.5456118e-12 | H127: ='2um Microsphere'!H4 -> 5.0430113e-15 | I127: ='2um Microsphere'!I4 -> 1.045e-06 | J127: ='2um Microsphere'!J4 -> 1.9697786e-08
A128: ='2um Microsphere'!A5 -> N/A | B128: ='2um Microsphere'!B5 -> N/A | C128: ='2um Microsphere'!C5 -> Maximum Size, Minimum Charge: 2um Carboxylate-Modified Polystyrene Microsphere | D128: ='2um Microsphere'!D5 -> N/A | E128: ='2um Microsphere'!E5 -> N/A | F128: ='2um Microsphere'!F5 -> N/A | G128: =ABS('2um Microsphere'!G5) -> 3.3772121e-12 | H128: ='2um Microsphere'!H5 -> 8.6311986e-15 | I128: ='2um Microsphere'!I5 -> 1.25e-06 | J128: ='2um Microsphere'!J5 -> 2.3561945e-08
A129: ='2um Microsphere'!A6 -> N/A | B129: ='2um Microsphere'!B6 -> N/A | C129: ='2um Microsphere'!C6 -> Maximum Size, Maximum Charge: 2um Carboxylate-Modified Polystyrene Microsphere | D129: ='2um Microsphere'!D6 -> N/A | E129: ='2um Microsphere'!E6 -> N/A | F129: ='2um Microsphere'!F6 -> N/A | G129: =ABS('2um Microsphere'!G6) -> 3.9074535e-12 | H129: ='2um Microsphere'!H6 -> 8.6311986e-15 | I129: ='2um Microsphere'!I6 -> 1.25e-06 | J129: ='2um Microsphere'!J6 -> 2.3561945e-08

Sheet Constants
A1: Avogadro's Number | B1: 6.0221408e+23 | C1: 1/mol
A2: Elementary Charge | B2: 1.6e-19 | C2: C
A3: Electron Mass | B3: =0.00054858*10^-3 -> 5.4858e-07 | C3: kg/mol
A4: Faraday Constant | B4: 96485 | C4: C/mol
A5: Polystyrene Density | B5: 1055 | C5: kg/m^3
A6: Dynamic Viscosity of Water | B6: 0.001 | C6: Pa*s

Sheet Values
A1: Atomic Number | B1: Symbol | C1: Element | D1: Atomic Mass [kg] | E1: Atomic Radius [m] | F1: Charge Number | G1: Charge [C] | H1: Ionic Mass [kg] | I1: Ionic Radius [m] | J1: Zeta [kg/s]
A2: 1 | B2: H | C2: Hydrogen | D2: 1.6738234e-27 | E2: 1.2e-10 | F2: 1 | G2: =F2*Constants!$B$2 -> 1.6e-19 | H2: =D2-F2*Constants!$B$3/Constants!$B$1 -> 1.6729124e-27 | J2: =6*PI()*0.001*I2 -> 0
A3: =A2+1 -> 2 | B3: He | C3: Helium | D3: 6.6464737e-27 | E3: 1.4e-10 | J3: =6*PI()*0.001*I3 -> 0
A4: =A3+1 -> 3 | B4: Li | C4: Lithium | D4: 1.1623773e-26 | E4: 1.82e-10 | F4: 1 | G4: =F4*Constants!$B$2 -> 1.6e-19 | H4: =D4-F4*Constants!$B$3/Constants!$B$1 -> 1.1622863e-26 | I4: 7.6e-11 | J4: 3.4e-12
A5: =A4+1 -> 4 | B5: Be | C5: Beryllium | D5: 1.4965082e-26 | E5: 1.53e-10 | F5: 2 | G5: =F5*Constants!$B$2 -> 3.2e-19 | H5: =D5-F5*Constants!$B$3/Constants!$B$1 -> 1.496326e-26 | I5: 4.5e-11 | J5: =6*PI()*0.001*I5 -> 8.4823002e-13
A6: =A5+1 -> 5 | B6: B | C6: Boron | D6: 1.7950427e-26 | E6: 1.92e-10 | J6: =6*PI()*0.001*I6 -> 0
A7: =A6+1 -> 6 | B7: C | C7: Carbon | D7: 1.9944735e-26 | E7: 1.7e-10 | J7: =6*PI()*0.001*I7 -> 0
A8: =A7+1 -> 7 | B8: N | C8: Nitrogen | D8: 2.3259171e-26 | E8: 1.55e-10 | J8: =6*PI()*0.001*I8 -> 0
A9: =A8+1 -> 8 | B9: O | C9: Oxygen | D9: 2.6566965e-26 | E9: 1.52e-10 | F9: -2 | G9: =F9*Constants!$B$2 -> -3.2e-19 | H9: =D9-F9*Constants!$B$3/Constants!$B$1 -> 2.6568786e-26 | I9: 1.4e-10 | J9: =6*PI()*0.001*I9 -> 2.6389378e-12
A10: =A9+1 -> 9 | B10: F | C10: Fluorine | D10: 3.1547591e-26 | E10: 1.35e-10 | F10: -1 | G10: =F10*Constants!$B$2 -> -1.6e-19 | H10: =D10-F10*Constants!$B$3/Constants!$B$1 -> 3.1548502e-26 | I10: 1.33e-10 | J10: =6*PI()*0.001*I10 -> 2.5069909e-12
A11: =A10+1 -> 10 | B11: Ne | C11: Neon | D11: 3.3509678e-26 | E11: 1.54e-10 | J11: =6*PI()*0.001*I11 -> 0
A12: =A11+1 -> 11 | B12: Na | C12: Sodium | D12: 3.817541e-26 | E12: 2.27e-10 | F12: 1 | G12: =F12*Constants!$B$2 -> 1.6e-19 | H12: =D12-F12*Constants!$B$3/Constants!$B$1 -> 3.8174499e-26 | I12: 1.02e-10 | J12: 3.2e-12
A13: =A12+1 -> 12 | B13: Mg | C13: Magnesium | D13: 4.0359402e-26 | E13: 1.73e-10 | F13: 2 | G13: =F13*Constants!$B$2 -> 3.2e-19 | H13: =D13-F13*Constants!$B$3/Constants!$B$1 -> 4.035758e-26 | I13: 7.2e-11 | J13: =6*PI()*0.001*I13 -> 1.357168e-12
A14: =A13+1 -> 13 | B14: Al | C14: Aluminum | D14: 4.4803898e-26 | E14: 1.84e-10 | F14: 3 | G14: =F14*Constants!$B$2 -> 4.8e-19 | H14: =D14-F14*Constants!$B$3/Constants!$B$1 -> 4.4801165e-26 | I14: 5.35e-11 | J14: =6*PI()*0.001*I14 -> 1.0084512e-12
A15: =A14+1 -> 14 | B15: Si | C15: Silicon | D15: 4.663624e-26 | E15: 2.1e-10 | F15: 4 | G15: =F15*Constants!$B$2 -> 6.4e-19 | H15: =D15-F15*Constants!$B$3/Constants!$B$1 -> 4.6632596e-26 | I15: 4e-11 | J15: =6*PI()*0.001*I15 -> 7.5398224e-13
A16: =A15+1 -> 15 | B16: P | C16: Phosphorus | D16: 5.1433142e-26 | E16: 1.8e-10 | F16: -3 | G16: =F16*Constants!$B$2 -> -4.8e-19 | H16: =D16-F16*Constants!$B$3/Constants!$B$1 -> 5.1435875e-26 | I16: 2.12e-10 | J16: =6*PI()*0.001*I16 -> 3.9961059e-12
A17: =A16+1 -> 16 | B17: S | C17: Sulfur | D17: 5.3253488e-26 | E17: 1.8e-10 | F17: -2 | G17: =F17*Constants!$B$2 -> -3.2e-19 | H17: =D17-F17*Constants!$B$3/Constants!$B$1 -> 5.325531e-26 | I17: 1.84e-10 | J17: =6*PI()*0.001*I17 -> 3.4683183e-12
A18: =A17+1 -> 17 | B18: Cl | C18: Chlorine | D18: 5.886611e-26 | E18: 1.75e-10 | F18: -1 | G18: =F18*Constants!$B$2 -> -1.6e-19 | H18: =D18-F18*Constants!$B$3/Constants!$B$1 -> 5.8867021e-26 | I18: 1.81e-10 | J18: =6*PI()*0.001*I18 -> 3.4117696e-12
A19: =A18+1 -> 18 | B19: Ar | C19: Argon | D19: 6.6255509e-26 | E19: 1.88e-10 | J19: =6*PI()*0.001*I19 -> 0
A20: =A19+1 -> 19 | B20: K | C20: Potassium | D20: 6.4924255e-26 | E20: 2.75e-10 | F20: 1 | G20: =F20*Constants!$B$2 -> 1.6e-19 | H20: =D20-F20*Constants!$B$3/Constants!$B$1 -> 6.4923344e-26 | I20: 1.38e-10 | J20: =6*PI()*0.001*I20 -> 2.6012387e-12
A21: =A20+1 -> 20 | B21: Ca | C21: Calcium | D21: 6.6554406e-26 | E21: 2.31e-10 | F21: 2 | G21: =F21*Constants!$B$2 -> 3.2e-19 | H21: =D21-F21*Constants!$B$3/Constants!$B$1 -> 6.6552584e-26 | I21: 1e-10 | J21: =6*PI()*0.001*I21 -> 1.8849556e-12
A22: =A21+1 -> 21 | B22: Sc | C22: Scandium | D22: 7.4651045e-26 | E22: 2.11e-10 | F22: 3 | G22: =F22*Constants!$B$2 -> 4.8e-19 | H22: =D22-F22*Constants!$B$3/Constants!$B$1 -> 7.4648312e-26 | I22: 7.45e-11 | J22: =6*PI()*0.001*I22 -> 1.4042919e-12
A23: =A22+1 -> 22 | B23: Ti | C23: Titanium | D23: 7.9485024e-26 | E23: 1.87e-10 | F23: 3 | G23: =F23*Constants!$B$2 -> 4.8e-19 | H23: =D23-F23*Constants!$B$3/Constants!$B$1 -> 7.9482291e-26 | I23: 6.7e-11 | J23: =6*PI()*0.001*I23 -> 1.2629202e-12
A24: =A23+1 -> 23 | B24: V | C24: Vanadium | D24: 8.4590351e-26 | E24: 1.79e-10 | F24: 2 | G24: =F24*Constants!$B$2 -> 3.2e-19 | H24: =D24-F24*Constants!$B$3/Constants!$B$1 -> 8.4588529e-26 | I24: 7.9e-11 | J24: =6*PI()*0.001*I24 -> 1.4891149e-12
A25: =A24+1 -> 24 | B25: Cr | C25: Chromium | D25: 8.6341389e-26 | E25: 1.89e-10 | F25: 2 | G25: =F25*Constants!$B$2 -> 3.2e-19 | H25: =D25-F25*Constants!$B$3/Constants!$B$1 -> 8.6339567e-26 | I25: 8e-11 | J25: =6*PI()*0.001*I25 -> 1.5079645e-12
A26: =A25+1 -> 25 | B26: Mn | C26: Manganese | D26: 9.1226762e-26 | E26: 1.97e-10 | F26: 2 | G26: =F26*Constants!$B$2 -> 3.2e-19 | H26: =D26-F26*Constants!$B$3/Constants!$B$1 -> 9.122494e-26 | I26: 8.3e-11 | J26: =6*PI()*0.001*I26 -> 1.5645131e-12
A27: =A26+1 -> 26 | B27: Fe | C27: Iron | D27: 9.2724502e-26 | E27: 1.94e-10 | F27: 2 | G27: =F27*Constants!$B$2 -> 3.2e-19 | H27: =D27-F27*Constants!$B$3/Constants!$B$1 -> 9.272268e-26 | I27: 7.8e-11 | J27: =6*PI()*0.001*I27 -> 1.4702654e-12
A28: =A27+1 -> 27 | B28: Co | C28: Cobalt | D28: 9.7860864e-26 | E28: 1.92e-10 | F28: 2 | G28: =F28*Constants!$B$2 -> 3.2e-19 | H28: =D28-F28*Constants!$B$3/Constants!$B$1 -> 9.7859042e-26 | I28: 7.45e-11 | J28: =6*PI()*0.001*I28 -> 1.4042919e-12
A29: =A28+1 -> 28 | B29: Ni | C29: Nickel | D29: 9.7462019e-26 | E29: 1.63e-10 | F29: 2 | G29: =F29*Constants!$B$2 -> 3.2e-19 | H29: =D29-F29*Constants!$B$3/Constants!$B$1 -> 9.7460198e-26 | I29: 6.9e-11 | J29: =6*PI()*0.001*I29 -> 1.3006194e-12
A30: =A29+1 -> 29 | B30: Cu | C30: Copper | D30: 1.0552726e-25 | E30: 1.4e-10 | F30: 2 | G30: =F30*Constants!$B$2 -> 3.2e-19 | H30: =D30-F30*Constants!$B$3/Constants!$B$1 -> 1.0552544e-25 | I30: 7.3e-11 | J30: =6*PI()*0.001*I30 -> 1.3760176e-12
A31: =A30+1 -> 30 | B31: Zn | C31: Zinc | D31: 1.0859925e-25 | E31: 1.39e-10 | F31: 2 | G31: =F31*Constants!$B$2 -> 3.2e-19 | H31: =D31-F31*Constants!$B$3/Constants!$B$1 -> 1.0859743e-25 | I31: 7.4e-11 | J31: =6*PI()*0.001*I31 -> 1.3948671e-12
... A36: =A35+1 -> 35 | B36: Br | C36: Bromine | D36: 1.3267707e-25 | E36: 1.83e-10 | F36: -1 | G36: =F36*Constants!$B$2 -> -1.6e-19 | H36: =D36-F36*Constants!$B$3/Constants!$B$1 -> 1.3267798e-25 | I36: 1.96e-10 | J36: =6*PI()*0.001*I36 -> 3.694513e-12
A37: =A36+1 -> 36 | B37: Kr | C37: Krypton | D37: 1.3915317e-25 | E37: 2.02e-10 | J37: =6*PI()*0.001*I37 -> 0
A38: =A37+1 -> 37 | B38: Rb | C38: Rubidium | D38: 1.4192295e-25 | E38: 3.03e-10 | F38: 1 | G38: =F38*Constants!$B$2 -> 1.6e-19 | H38: =D38-F38*Constants!$B$3/Constants!$B$1 -> 1.4192204e-25 | I38: 1.52e-10 | J38: =6*PI()*0.001*I38 -> 2.8651325e-12
A39: =A38+1 -> 38 | B39: Sr | C39: Strontium | D39: 1.4549643e-25 | E39: 2.49e-10 | F39: 2 | G39: =F39*Constants!$B$2 -> 3.2e-19 | H39: =D39-F39*Constants!$B$3/Constants!$B$1 -> 1.4549461e-25 | I39: 1.18e-10 | J39: =6*PI()*0.001*I39 -> 2.2242476e-12
A40: =A39+1 -> 39 | B40: Y | C40: Yttrium | D40: 1.4763162e-25 | E40: 2.19e-10 | F40: 3 | G40: =F40*Constants!$B$2 -> 4.8e-19 | H40: =D40-F40*Constants!$B$3/Constants!$B$1 -> 1.4762889e-25 | I40: 9e-11 | J40: =6*PI()*0.001*I40 -> 1.69646e-12
A41: =A40+1 -> 40 | B41: Zr | C41: Zirconium | D41: 1.5147437e-25 | E41: 1.86e-10 | F41: 4 | G41: =F41*Constants!$B$2 -> 6.4e-19 | H41: =D41-F41*Constants!$B$3/Constants!$B$1 -> 1.5147073e-25 | I41: 7.2e-11 | J41: =6*PI()*0.001*I41 -> 1.357168e-12
A42: =A41+1 -> 41 | B42: Nb | C42: Niobium | D42: 1.5427466e-25 | E42: 2.07e-10 | F42: 3 | G42: =F42*Constants!$B$2 -> 4.8e-19 | H42: =D42-F42*Constants!$B$3/Constants!$B$1 -> 1.5427192e-25 | I42: 7.2e-11 | J42: =6*PI()*0.001*I42 -> 1.357168e-12
A43: =A42+1 -> 42 | B43: Mo | C43: Molybdenum | D43: 1.5932872e-25 | E43: 2.09e-10 | F43: 4 | G43: =F43*Constants!$B$2 -> 6.4e-19 | H43: =D43-F43*Constants!$B$3/Constants!$B$1 -> 1.5932508e-25 | I43: 6.5e-11 | J43: =6*PI()*0.001*I43 -> 1.2252211e-12
A44: =A43+1 -> 43 | B44: Tc | C44: Technetium | D44: 1.609168e-25 | E44: 2.09e-10 | F44: 4 | G44: =F44*Constants!$B$2 -> 6.4e-19 | H44: =D44-F44*Constants!$B$3/Constants!$B$1 -> 1.6091315e-25 | I44: 6.45e-11 | J44: =6*PI()*0.001*I44 -> 1.2157964e-12
...

Sheet Quantum Dot
A1: Atomic Number | B1: Symbol | C1: Element | D1: Atomic Mass [kg] | E1: Atomic Radius [m] | F1: Charge Number | G1: Charge [C] | H1: Ionic Mass [kg] | I1: Ionic Radius [m] | J1: Zeta [kg/s]
A2: 1 | B2: H | C2: Hydrogen | D2: 1.6738234e-27 | E2: 1.2e-10 | F2: 1 | G2: =F2*Constants!$B$2 -> 1.6e-19 | H2: =D2-F2*Constants!$B$3/Constants!$B$1 -> 1.6729124e-27 | J2: =6*PI()*0.001*I2 -> 0 | K2: =H2/G2 -> 1.0455703e-08 | L2: =K2^-1 -> 95641587
A3: =A2+1 -> 2 | B3: He | C3: Helium | D3: 6.6464737e-27 | E3: 1.4e-10 | J3: =6*PI()*0.001*I3 -> 0
A4: =A3+1 -> 3 | B4: Li | C4: Lithium | D4: 1.1623773e-26 | E4: 1.82e-10 | F4: 1 | G4: =F4*Constants!$B$2 -> 1.6e-19 | H4: =D4-F4*Constants!$B$3/Constants!$B$1 -> 1.1622863e-26 | I4: 7.6e-11 | J4: =6*PI()*0.001*I4 -> 1.4325663e-12 | K4: =H4/G4 -> 7.2642891e-08 | L4: =K4^-1 -> 13765972 | M4: =ABS(J4/G4) -> 8953539.1
A5: =A4+1 -> 4 | B5: Be | C5: Beryllium | D5: 1.4965082e-26 | E5: 1.53e-10 | F5: 2 | G5: =F5*Constants!$B$2 -> 3.2e-19 | H5: =D5-F5*Constants!$B$3/Constants!$B$1 -> 1.496326e-26 | I5: 4.5e-11 | J5: =6*PI()*0.001*I5 -> 8.4823002e-13 | K5: =H5/G5 -> 4.6760188e-08 | L5: =K5^-1 -> 21385714
A6: =A5+1 -> 5 | B6: B | C6: Boron | D6: 1.7950427e-26 | E6: 1.92e-10 | J6: =6*PI()*0.001*I6 -> 0
A7: =A6+1 -> 6 | B7: C | C7: Carbon | D7: 1.9944735e-26 | E7: 1.7e-10 | J7: =6*PI()*0.001*I7 -> 0
A8: =A7+1 -> 7 | B8: N | C8: Nitrogen | D8: 2.3259171e-26 | E8: 1.55e-10 | J8: =6*PI()*0.001*I8 -> 0
A9: =A8+1 -> 8 | B9: O | C9: Oxygen | D9: 2.6566965e-26 | E9: 1.52e-10 | F9: -2 | G9: =F9*Constants!$B$2 -> -3.2e-19 | H9: =D9-F9*Constants!$B$3/Constants!$B$1 -> 2.6568786e-26 | I9: 1.4e-10 | J9: =6*PI()*0.001*I9 -> 2.6389378e-12 | K9: =H9/G9 -> -8.3027458e-08 | L9: =K9^-1 -> -12044208
A10: =A9+1 -> 9 | B10: F | C10: Fluorine | D10: 3.1547591e-26 | E10: 1.35e-10 | F10: -1 | G10: =F10*Constants!$B$2 -> -1.6e-19 | H10: =D10-F10*Constants!$B$3/Constants!$B$1 -> 3.1548502e-26 | I10: 1.33e-10 | J10: =6*PI()*0.001*I10 -> 2.5069909e-12 | K10: =H10/G10 -> -1.9717813e-07 | L10: =K10^-1 -> -5071556.2
A11: =A10+1 -> 10 | B11: Ne | C11: Neon | D11: 3.3509678e-26 | E11: 1.54e-10 | J11: =6*PI()*0.001*I11 -> 0
A12: =A11+1 -> 11 | B12: Na | C12: Sodium | D12: 3.817541e-26 | E12: 2.27e-10 | F12: 1 | G12: =F12*Constants!$B$2 -> 1.6e-19 | H12: =D12-F12*Constants!$B$3/Constants!$B$1 -> 3.8174499e-26 | I12: 1.02e-10 | J12: =6*PI()*0.001*I12 -> 1.9226547e-12 | K12: =H12/G12 -> 2.3859062e-07 | L12: =K12^-1 -> 4191279.6
A13: =A12+1 -> 12 | B13: Mg | C13: Magnesium | D13: 4.0359402e-26 | E13: 1.73e-10 | F13: 2 | G13: =F13*Constants!$B$2 -> 3.2e-19 | H13: =D13-F13*Constants!$B$3/Constants!$B$1 -> 4.035758e-26 | I13: 7.2e-11 | J13: =6*PI()*0.001*I13 -> 1.357168e-12 | K13: =H13/G13 -> 1.2611744e-07 | L13: =K13^-1 -> 7929117.6
A14: =A13+1 -> 13 | B14: Al | C14: Aluminum | D14: 4.4803898e-26 | E14: 1.84e-10 | F14: 3 | G14: =F14*Constants!$B$2 -> 4.8e-19 | H14: =D14-F14*Constants!$B$3/Constants!$B$1 -> 4.4801165e-26 | I14: 5.35e-11 | J14: =6*PI()*0.001*I14 -> 1.0084512e-12 | K14: =H14/G14 -> 9.3335761e-08 | L14: =K14^-1 -> 10714007
A15: =A14+1 -> 14 | B15: Si | C15: Silicon | D15: 4.663624e-26 | E15: 2.1e-10 | F15: 4 | G15: =F15*Constants!$B$2 -> 6.4e-19 | H15: =D15-F15*Constants!$B$3/Constants!$B$1 -> 4.6632596e-26 | I15: 4e-11 | J15: =6*PI()*0.001*I15 -> 7.5398224e-13 | K15: =H15/G15 -> 7.2863431e-08 | L15: =K15^-1 -> 13724306
A16: =A15+1 -> 15 | B16: P | C16: Phosphorus | D16: 5.1433142e-26 | E16: 1.8e-10 | F16: -3 | G16: =F16*Constants!$B$2 -> -4.8e-19 | H16: =D16-F16*Constants!$B$3/Constants!$B$1 -> 5.1435875e-26 | I16: 2.12e-10 | J16: =6*PI()*0.001*I16 -> 3.9961059e-12 | K16: =H16/G16 -> -1.0715807e-07 | L16: =K16^-1 -> -9332008.1
A17: =A16+1 -> 16 | B17: S | C17: Sulfur | D17: 5.3253488e-26 | E17: 1.8e-10 | F17: -2 | G17: =F17*Constants!$B$2 -> -3.2e-19 | H17: =D17-F17*Constants!$B$3/Constants!$B$1 -> 5.325531e-26 | I17: 1.84e-10 | J17: =6*PI()*0.001*I17 -> 3.4683183e-12 | K17: =H17/G17 -> -1.6642284e-07 | L17: =K17^-1 -> -6008790.5
A18: =A17+1 -> 17 | B18: Cl | C18: Chlorine | D18: 5.886611e-26 | E18: 1.75e-10 | F18: -1 | G18: =F18*Constants!$B$2 -> -1.6e-19 | H18: =D18-F18*Constants!$B$3/Constants!$B$1 -> 5.8867021e-26 | I18: 1.81e-10 | J18: =6*PI()*0.001*I18 -> 3.4117696e-12 | K18: =H18/G18 -> -3.6791888e-07 | L18: =K18^-1 -> -2717990.4
A19: =A18+1 -> 18 | B19: Ar | C19: Argon | D19: 6.6255509e-26 | E19: 1.88e-10 | J19: =6*PI()*0.001*I19 -> 0
A20: =A19+1 -> 19 | B20: K | C20: Potassium | D20: 6.4924255e-26 | E20: 2.75e-10 | F20: 1 | G20: =F20*Constants!$B$2 -> 1.6e-19 | H20: =D20-F20*Constants!$B$3/Constants!$B$1 -> 6.4923344e-26 | I20: 1.38e-10 | J20: =6*PI()*0.001*I20 -> 2.6012387e-12 | K20: =H20/G20 -> 4.057709e-07 | L20: =K20^-1 -> 2464444.9
A21: =A20+1 -> 20 | B21: Ca | C21: Calcium | D21: 6.6554406e-26 | E21: 2.31e-10 | F21: 2 | G21: =F21*Constants!$B$2 -> 3.2e-19 | H21: =D21-F21*Constants!$B$3/Constants!$B$1 -> 6.6552584e-26 | I21: 1e-10 | J21: =6*PI()*0.001*I21 -> 1.8849556e-12 | K21: =H21/G21 -> 2.0797682e-07 | L21: =K21^-1 -> 4808228
A22: =A21+1 -> 21 | B22: Sc | C22: Scandium | D22: 7.4651045e-26 | E22: 2.11e-10 | F22: 3 | G22: =F22*Constants!$B$2 -> 4.8e-19 | H22: =D22-F22*Constants!$B$3/Constants!$B$1 -> 7.4648312e-26 | I22: 7.45e-11 | J22: =6*PI()*0.001*I22 -> 1.4042919e-12 | K22: =H22/G22 -> 1.5551732e-07 | L22: =K22^-1 -> 6430152.1
A23: =A22+1 -> 22 | B23: Ti | C23: Titanium | D23: 7.9485024e-26 | E23: 1.87e-10 | F23: 3 | G23: =F23*Constants!$B$2 -> 4.8e-19 | H23: =D23-F23*Constants!$B$3/Constants!$B$1 -> 7.9482291e-26 | I23: 6.7e-11 | J23: =6*PI()*0.001*I23 -> 1.2629202e-12 | K23: =H23/G23 -> 1.6558811e-07 | L23: =K23^-1 -> 6039081.1
A24: =A23+1 -> 23 | B24: V | C24: Vanadium | D24: 8.4590351e-26 | E24: 1.79e-10 | F24: 2 | G24: =F24*Constants!$B$2 -> 3.2e-19 | H24: =D24-F24*Constants!$B$3/Constants!$B$1 -> 8.4588529e-26 | I24: 7.9e-11 | J24: =6*PI()*0.001*I24 -> 1.4891149e-12 | K24: =H24/G24 -> 2.6433915e-07 | L24: =K24^-1 -> 3783018.9
A25: =A24+1 -> 24 | B25: Cr | C25: Chromium | D25: 8.6341389e-26 | E25: 1.89e-10 | F25: 2 | G25: =F25*Constants!$B$2 -> 3.2e-19 | H25: =D25-F25*Constants!$B$3/Constants!$B$1 -> 8.6339567e-26 | I25: 8e-11 | J25: =6*PI()*0.001*I25 -> 1.5079645e-12 | K25: =H25/G25 -> 2.6981115e-07 | L25: =K25^-1 -> 3706296.1
A26: =A25+1 -> 25 | B26: Mn | C26: Manganese | D26: 9.1226762e-26 | E26: 1.97e-10 | F26: 2 | G26: =F26*Constants!$B$2 -> 3.2e-19 | H26: =D26-F26*Constants!$B$3/Constants!$B$1 -> 9.122494e-26 | I26: 8.3e-11 | J26: =6*PI()*0.001*I26 -> 1.5645131e-12 | K26: =H26/G26 -> 2.8507794e-07 | L26: =K26^-1 -> 3507812.7
A27: =A26+1 -> 26 | B27: Fe | C27: Iron | D27: 9.2724502e-26 | E27: 1.94e-10 | F27: 2 | G27: =F27*Constants!$B$2 -> 3.2e-19 | H27: =D27-F27*Constants!$B$3/Constants!$B$1 -> 9.272268e-26 | I27: 7.8e-11 | J27: =6*PI()*0.001*I27 -> 1.4702654e-12 | K27: =H27/G27 -> 2.8975837e-07 | L27: =K27^-1 -> 3451151.3
A28: =A27+1 -> 27 | B28: Co | C28: Cobalt | D28: 9.7860864e-26 | E28: 1.92e-10 | F28: 2 | G28: =F28*Constants!$B$2 -> 3.2e-19 | H28: =D28-F28*Constants!$B$3/Constants!$B$1 -> 9.7859042e-26 | I28: 7.45e-11 | J28: =6*PI()*0.001*I28 -> 1.4042919e-12 | K28: =H28/G28 -> 3.0580951e-07 | L28: =K28^-1 -> 3270009.5
A29: =A28+1 -> 28 | B29: Ni | C29: Nickel | D29: 9.7462019e-26 | E29: 1.63e-10 | F29: 2 | G29: =F29*Constants!$B$2 -> 3.2e-19 | H29: =D29-F29*Constants!$B$3/Constants!$B$1 -> 9.7460198e-26 | I29: 6.9e-11 | J29: =6*PI()*0.001*I29 -> 1.3006194e-12 | K29: =H29/G29 -> 3.0456312e-07 | L29: =K29^-1 -> 3283391.7
A30: =A29+1 -> 29 | B30: Cu | C30: Copper | D30: 1.0552726e-25 | E30: 1.4e-10 | F30: 2 | G30: =F30*Constants!$B$2 -> 3.2e-19 | H30: =D30-F30*Constants!$B$3/Constants!$B$1 -> 1.0552544e-25 | I30: 7.3e-11 | J30: =6*PI()*0.001*I30 -> 1.3760176e-12 | K30: =H30/G30 -> 3.2976699e-07 | L30: =K30^-1 -> 3032444.2
A31: =A30+1 -> 30 | B31: Zn | C31: Zinc | D31: 1.0859925e-25 | E31: 1.39e-10 | F31: 2 | G31: =F31*Constants!$B$2 -> 3.2e-19 | H31: =D31-F31*Constants!$B$3/Constants!$B$1 -> 1.0859743e-25 | I31: 7.4e-11 | J31: =6*PI()*0.001*I31 -> 1.3948671e-12 | K31: =H31/G31 -> 3.3936698e-07 | L31: =K31^-1 -> 2946662.6
... A36: =A35+1 -> 35 | B36: Br | C36: Bromine | D36: 1.3267707e-25 | E36: 1.83e-10 | F36: -1 | G36: =F36*Constants!$B$2 -> -1.6e-19 | H36: =D36-F36*Constants!$B$3/Constants!$B$1 -> 1.3267798e-25 | I36: 1.96e-10 | J36: =6*PI()*0.001*I36 -> 3.694513e-12 | K36: =H36/G36 -> -8.2923739e-07 | L36: =K36^-1 -> -1205927.3
A37: =A36+1 -> 36 | B37: Kr | C37: Krypton | D37: 1.3915317e-25 | E37: 2.02e-10 | J37: =6*PI()*0.001*I37 -> 0
A38: =A37+1 -> 37 | B38: Rb | C38: Rubidium | D38: 1.4192295e-25 | E38: 3.03e-10 | F38: 1 | G38: =F38*Constants!$B$2 -> 1.6e-19 | H38: =D38-F38*Constants!$B$3/Constants!$B$1 -> 1.4192204e-25 | I38: 1.52e-10 | J38: =6*PI()*0.001*I38 -> 2.8651325e-12 | K38: =H38/G38 -> 8.8701276e-07 | L38: =K38^-1 -> 1127379.5
A39: =A38+1 -> 38 | B39: Sr | C39: Strontium | D39: 1.4549643e-25 | E39: 2.49e-10 | F39: 2 | G39: =F39*Constants!$B$2 -> 3.2e-19 | H39: =D39-F39*Constants!$B$3/Constants!$B$1 -> 1.4549461e-25 | I39: 1.18e-10 | J39: =6*PI()*0.001*I39 -> 2.2242476e-12 | K39: =H39/G39 -> 4.5467066e-07 | L39: =K39^-1 -> 2199394.2
A40: =A39+1 -> 39 | B40: Y | C40: Yttrium | D40: 1.4763162e-25 | E40: 2.19e-10 | F40: 3 | G40: =F40*Constants!$B$2 -> 4.8e-19 | H40: =D40-F40*Constants!$B$3/Constants!$B$1 -> 1.4762889e-25 | I40: 9e-11 | J40: =6*PI()*0.001*I40 -> 1.69646e-12 | K40: =H40/G40 -> 3.0756018e-07 | L40: =K40^-1 -> 3251396.2
A41: =A40+1 -> 40 | B41: Zr | C41: Zirconium | D41: 1.5147437e-25 | E41: 1.86e-10 | F41: 4 | G41: =F41*Constants!$B$2 -> 6.4e-19 | H41: =D41-F41*Constants!$B$3/Constants!$B$1 -> 1.5147073e-25 | I41: 7.2e-11 | J41: =6*PI()*0.001*I41 -> 1.357168e-12 | K41: =H41/G41 -> 2.3667302e-07 | L41: =K41^-1 -> 4225238.8
A42: =A41+1 -> 41 | B42: Nb | C42: Niobium | D42: 1.5427466e-25 | E42: 2.07e-10 | F42: 3 | G42: =F42*Constants!$B$2 -> 4.8e-19 | H42: =D42-F42*Constants!$B$3/Constants!$B$1 -> 1.5427192e-25 | I42: 7.2e-11 | J42: =6*PI()*0.001*I42 -> 1.357168e-12 | K42: =H42/G42 -> 3.2139984e-07 | L42: =K42^-1 -> 3111389.2
A43: =A42+1 -> 42 | B43: Mo | C43: Molybdenum | D43: 1.5932872e-25 | E43: 2.09e-10 | F43: 4 | G43: =F43*Constants!$B$2 -> 6.4e-19 | H43: =D43-F43*Constants!$B$3/Constants!$B$1 -> 1.5932508e-25 | I43: 6.5e-11 | J43: =6*PI()*0.001*I43 -> 1.2252211e-12 | K43: =H43/G43 -> 2.4894544e-07 | L43: =K43^-1 -> 4016944.5
A44: =A43+1 -> 43 | B44: Tc | C44: Technetium | D44: 1.609168e-25 | E44: 2.09e-10 | F44: 4 | G44: =F44*Constants!$B$2 -> 6.4e-19 | H44: =D44-F44*Constants!$B$3/Constants!$B$1 -> 1.6091315e-25 | I44: 6.45e-11 | J44: =6*PI()*0.001*I44 -> 1.2157964e-12 | K44: =H44/G44 -> 2.514268e-07 | L44: =K44^-1 -> 3977300.7
...

Sheet 10um Microsphere
A1: Atomic Number | B1: Symbol | C1: Microsphere | D1: Atomic Mass [kg] | E1: Atomic Radius [m] | F1: Charge Number | G1: Charge [C] | H1: Mass [kg] | I1: Ionic Radius [m] | J1: Zeta [kg/s] | K1: Q/zeta
A2: N/A | B2: N/A | C2: Minimum Size, Minimum Charge: 10um Carboxylate-Modified Polystyrene Microsphere | D2: N/A | E2: N/A | F2: N/A | G2: =ABS(4*PI()*I2^2*B15*-1*Constants!$B$2) -> 4.5338721e-11 | H2: =4/3*PI()*I2^3*Constants!$B$5 -> 4.2455846e-13 | I2: =0.00000916/2 -> 4.58e-06 | J2: =I2*6*PI()*Constants!$B$6 -> 8.6330966e-08 | K2: =G2/J2 -> 0.00052517333
A3: N/A | B3: N/A | C3: Maximum Size, Minimum Charge: 10um Carboxylate-Modified Polystyrene Microsphere | D3: N/A | E3: N/A | F3: N/A | G3: =ABS(4*PI()*I3^2*B15*-1*Constants!$B$2) -> 6.1865122e-11 | H3: =4/3*PI()*I3^3*Constants!$B$5 -> 6.7670972e-13 | I3: =0.0000107/2 -> 5.35e-06 | J3: =I3*6*PI()*Constants!$B$6 -> 1.0084512e-07 | K3: =G3/J3 -> 0.00061346667
A4: N/A | B4: N/A | C4: Average: 10um Carboxylate-Modified Polystyrene Microsphere | D4: N/A | E4: N/A | F4: N/A | G4: =ABS(4*PI()*I4^2*AVERAGE(B15:B16)*-1*Constants!$B$2) -> 7.0118167e-11 | H4: =4/3*PI()*I4^3*Constants!$B$5 -> 5.4087739e-13 | I4: =AVERAGE(I2,I3) -> 4.965e-06 | J4: =I4*6*PI()*Constants!$B$6 -> 9.3588045e-08 | K4: =G4/J4 -> 0.0007492214
A5: N/A | B5: N/A | C5: Minimum Size, Maximum Charge: 10um Carboxylate-Modified Polystyrene Microsphere | D5: N/A | E5: N/A | F5: N/A | G5: =ABS(4*PI()*I5^2*B16*-1*Constants!$B$2) -> 7.3992201e-11 | H5: =4/3*PI()*I5^3*Constants!$B$5 -> 4.2455846e-13 | I5: =0.00000916/2 -> 4.58e-06 | J5: =I5*6*PI()*Constants!$B$6 -> 8.6330966e-08 | K5: =G5/J5 -> 0.00085707602
A6: N/A | B6: N/A | C6: Maximum Size, Maximum Charge: 10um Carboxylate-Modified Polystyrene Microsphere | D6: N/A | E6: N/A | F6: N/A | G6: =ABS(4*PI()*I6^2*B16*-1*Constants!$B$2) -> 1.0096307e-10 | H6: =4/3*PI()*I6^3*Constants!$B$5 -> 6.7670972e-13 | I6: =0.0000107/2 -> 5.35e-06 | J6: =I6*6*PI()*Constants!$B$6 -> 1.0084512e-07 | K6: =G6/J6 -> 0.0010011696
A15: Min Charge Density | B15: 1.075e+18 | C15: COOH/m^2
A16: Max Charge Density | B16: =(1/57)*10^20 -> 1.754386e+18 | C16: COOH/m^2

Sheet 2um Microsphere
A1: Atomic Number | B1: Symbol | C1: Microsphere | D1: Atomic Mass [kg] | E1: Atomic Radius [m] | F1: Charge Number | G1: Charge [C] | H1: Mass [kg] | I1: Ionic Radius [m] | J1: Zeta [kg/s] | K1: Q/zeta
A2: N/A | B2: N/A | C2: Minimum Size, Minimum Charge: 2um Carboxylate-Modified Polystyrene Microsphere | D2: N/A | E2: N/A | F2: N/A | G2: =ABS(4*PI()*I2^2*B15*-1*Constants!$B$2) -> 1.525095e-12 | H2: =4/3*PI()*I2^3*Constants!$B$5 -> 2.6192619e-15 | I2: =0.00000168/2 -> 8.4e-07 | J2: =I2*6*PI()*Constants!$B$6 -> 1.5833627e-08 | K2: =G2/J2 -> 9.632e-05
A3: N/A | B3: N/A | C3: Minimum Size, Maximum Charge: 2um Carboxylate-Modified Polystyrene Microsphere | D3: N/A | E3: N/A | F3: N/A | G3: =ABS(4*PI()*I3^2*B16*-1*Constants!$B$2) -> 1.7645435e-12 | H3: =4/3*PI()*I3^3*Constants!$B$5 -> 2.6192619e-15 | I3: =0.00000168/2 -> 8.4e-07 | J3: =I3*6*PI()*Constants!$B$6 -> 1.5833627e-08 | K3: =G3/J3 -> 0.00011144279
A4: N/A | B4: N/A | C4: Average: 2um Carboxylate-Modified Polystyrene Microsphere | D4: N/A | E4: N/A | F4: N/A | G4: =ABS(4*PI()*I4^2*AVERAGE(B15:B16)*-1*Constants!$B$2) -> 2.5456118e-12 | H4: =4/3*PI()*I4^3*Constants!$B$5 -> 5.0430113e-15 | I4: =AVERAGE(I2,I5) -> 1.045e-06 | J4: =I4*6*PI()*Constants!$B$6 -> 1.9697786e-08 | K4: =G4/J4 -> 0.0001292334
A5: N/A | B5: N/A | C5: Maximum Size, Minimum Charge: 2um Carboxylate-Modified Polystyrene Microsphere | D5: N/A | E5: N/A | F5: N/A | G5: =ABS(4*PI()*I5^2*B15*-1*Constants!$B$2) -> 3.3772121e-12 | H5: =4/3*PI()*I5^3*Constants!$B$5 -> 8.6311986e-15 | I5: =0.0000025/2 -> 1.25e-06 | J5: =I5*6*PI()*Constants!$B$6 -> 2.3561945e-08 | K5: =G5/J5 -> 0.00014333333
A6: N/A | B6: N/A | C6: Maximum Size, Maximum Charge: 2um Carboxylate-Modified Polystyrene Microsphere | D6: N/A | E6: N/A | F6: N/A | G6: =ABS(4*PI()*I6^2*B16*-1*Constants!$B$2) -> 3.9074535e-12 | H6: =4/3*PI()*I6^3*Constants!$B$5 -> 8.6311986e-15 | I6: =0.0000025/2 -> 1.25e-06 | J6: =I6*6*PI()*Constants!$B$6 -> 2.3561945e-08 | K6: =G6/J6 -> 0.00016583748
A15: Min Charge Density | B15: 1.075e+18 | C15: COOH/m^2
A16: Max Charge Density | B16: =(1/80.4)*10^20 -> 1.2437811e+18 | C16: COOH/m^2
